
**Android 复习笔记 - 1.3.4 协程的取消与异常处理 (深入)**

**1. 核心价值 / 解决的问题 (Why it exists / What problem it solves):**

*   **核心价值：** 健壮的并发系统必须能够优雅地处理任务的取消和运行过程中可能发生的异常。Kotlin 协程通过其结构化并发模型，提供了强大且一致的取消传播机制和异常处理机制，这使得开发者能够更容易地编写出在面对错误和生命周期变化时行为可预测、资源可控的异步代码。
*   **解决的问题：**
    *   **资源泄漏：** 如果异步任务在其关联的组件（如 `Activity`）销毁后没有被正确取消，可能导致内存泄漏和不必要的后台资源消耗（如网络、CPU）。
    *   **僵尸任务：** 已不再需要或已失败的任务仍在运行。
    *   **复杂的取消逻辑：** 手动管理多个关联异步任务的取消状态非常容易出错。
    *   **分散的异常处理：** 传统异步编程中，每个回调或线程可能需要单独处理异常，难以形成统一的错误处理策略。
    *   **应用崩溃：** 未捕获的异常可能导致应用崩溃。

**2. 知识点阐述 (Is what? Core principles?):**

*   **2.A 协程的取消 (Cancellation):**
    *   **协作式取消 (Cooperative Cancellation)：**
        *   协程的取消不是抢占式的（即不能像终止线程那样强行停止）。**协程代码必须主动配合取消操作才能生效。**
        *   当一个协程被取消时，它会进入“取消中 (Cancelling)”状态，并最终进入“已取消 (Cancelled)”状态。
        *   取消是通过抛出 `CancellationException` 来实现的。这是一个特殊的异常，会被协程框架识别并用于正常的取消流程，通常不需要被显式捕获（除非有特定的清理逻辑）。
    *   **如何使协程代码响应取消：**
        1.  **定期检查 `isActive` 属性：**
            *   在长时间运行的计算密集型循环中，应定期检查 `coroutineContext[Job]?.isActive` (或直接在 `CoroutineScope` 内使用 `isActive`)。如果为 `false`，则应停止工作并退出。
            ```kotlin
            // launch {
            //     var i = 0
            //     while (isActive && i < 10000) { // Check isActive
            //         if (i % 100 == 0) Log.d(TAG, "Working... $i")
            //         // performSomeWorkUnit()
            //         i++
            //     }
            //     Log.d(TAG, "Coroutine finished or cancelled at i=$i")
            // }
            ```
        2.  **使用 `kotlinx.coroutines` 包中所有可挂起的函数：**
            *   大多数 `kotlinx.coroutines` 提供的挂起函数（如 `delay()`, `yield()`, `withContext()`, `async {}.await()`, `Flow` 的各种操作符和 `collect`）在执行前都会检查当前协程的取消状态。如果协程已被取消，它们会立即抛出 `CancellationException`。
            *   因此，在协程中合理地使用这些挂起函数，可以自然地使其响应取消。
        3.  **显式调用 `ensureActive()` 或 `yield()`:**
            *   `ensureActive()`: 检查当前 `Job` 是否处于活动状态，如果不是，则抛出 `CancellationException`。
            *   `yield()`: 检查取消状态，如果已取消则抛出 `CancellationException`；否则，它会将当前协程的执行权让给同一个调度器上的其他等待执行的协程（如果有的话），然后再恢复。这也有助于避免长时间占用线程。
    *   **触发取消：**
        *   调用 `Job.cancel(cause: CancellationException? = null)`。可以提供一个可选的 `cause` 来描述取消的原因。
        *   如果父 `Job` 被取消，其所有子 `Job` 也会被取消（结构化并发）。
        *   如果作用域 (`CoroutineScope`) 被取消 (`scope.cancel()`)，该作用域内的所有协程都会被取消。
    *   **处理取消后的清理工作：**
        *   **`try-finally` 块：** `finally` 块中的代码即使在协程因 `CancellationException` 而终止时也会被执行。
        *   **`NonCancellable` 上下文：**
            *   如果在 `finally` 块中需要执行**挂起函数**来进行清理（例如，释放一个需要异步操作的资源），那么这些挂起函数可能因为协程已被取消而无法执行。
            *   此时，应将清理逻辑包装在 `withContext(NonCancellable) { ... }` 中。`NonCancellable` 是一个特殊的 `Job`，它总是处于活动状态，在此上下文中启动的协程不会被外部取消影响。
            ```kotlin
            // job.invokeOnCompletion { cause ->
            //     if (cause is CancellationException) {
            //         Log.d(TAG, "Coroutine was cancelled: ${cause.message}")
            //     }
            //     // Perform non-suspending cleanup here
            // }
            //
            // launch {
            //     try {
            //         // ... do some work with a resource ...
            //         while (isActive) { delay(100) }
            //     } finally {
            //         Log.d(TAG, "Entering finally block")
            //         withContext(NonCancellable) { // Ensure suspending cleanup runs
            //             delay(500) // Simulate suspending cleanup
            //             Log.d(TAG, "Resource released in NonCancellable block.")
            //         }
            //     }
            // }
            ```
        *   **`Job.invokeOnCompletion { cause: Throwable? -> ... }`:** 注册一个回调，在协程完成时（无论正常完成、异常终止还是被取消）被调用。`cause` 参数可以用来判断完成的原因。

    *   **`TimeoutCancellationException`:**
        *   `withTimeout(timeMillis: Long) { ... }`: 如果代码块在指定时间内未完成，会抛出 `TimeoutCancellationException` 并取消该代码块内的协程。
        *   `withTimeoutOrNull(timeMillis: Long) { ... }`: 类似 `withTimeout`，但超时时返回 `null` 而不是抛出异常。

*   **2.B 协程的异常处理 (Exception Handling):**
    结构化并发对异常处理有重要影响。

    *   **异常的传播行为 (默认 - 使用普通 `Job`):**
        1.  **`launch` 构建的协程中未捕获的异常：**
            *   会被视为“未处理的异常”。
            *   它会**立即传播给其父 `Job`**。
            *   父 `Job` 会因此被取消。
            *   父 `Job` 的取消会进一步传播给其所有其他子协程，导致它们也被取消。
            *   最终，如果异常一直传播到根作用域（如 `viewModelScope`, `lifecycleScope`）且没有被 `CoroutineExceptionHandler` 处理，它可能会导致应用崩溃（类似于线程中未捕获的异常）。
        2.  **`async` 构建的协程中未捕获的异常：**
            *   异常**不会立即传播**给父 `Job`。
            *   它会被捕获并存储在返回的 `Deferred` 对象中。
            *   **当调用该 `Deferred` 对象的 `await()` 方法时，存储的异常才会被重新抛出。**
            *   如果 `await()` 时抛出的异常未被调用方 `try-catch`，则该异常会继续按上述 `launch` 的规则传播给父 `Job`。
        *   **`CancellationException` 是例外：** 它被认为是协程正常取消的一部分，通常不会导致父协程或作用域的失败（除非它是被其他非 `CancellationException` 异常间接引起的）。

    *   **处理异常的方式：**
        1.  **`try-catch` 块：**
            *   可以直接在协程体内部或调用挂起函数的地方使用标准的 `try-catch` 块来捕获和处理特定类型的异常。
            *   这是处理预期异常的首选方式。
            ```kotlin
            // viewModelScope.launch {
            //     try {
            //         val data = repository.fetchData() // Suspend fun that might throw IOException
            //         updateUi(data)
            //     } catch (e: IOException) {
            //         showNetworkError(e)
            //     } catch (e: Exception) {
            //         showGenericError(e)
            //     }
            // }
            ```
        2.  **`CoroutineExceptionHandler` (用于未捕获的异常)：**
            *   **是什么：** 一个 `CoroutineContext.Element`，用于处理在协程作用域内（或顶级协程中）那些**没有被 `try-catch` 捕获**的异常。
            *   **作用时机：** 只对通过 `launch` 启动的协程中未捕获的异常有效，或者当 `async` 的异常传播到调用 `await()` 的 `launch` 块且未被捕获时。
            *   **如何使用：**
                ```kotlin
                // val handler = CoroutineExceptionHandler { context, exception ->
                //     Log.e("AppCoroutine", "Unhandled exception in ${context[CoroutineName] ?: "Coroutine"}: $exception")
                //     // Typically log the error, report to crashlytics, maybe show a generic error message.
                //     // This handler CANNOT recover from the exception or prevent the coroutine (and its scope if using Job) from being cancelled.
                // }
                // val scope = CoroutineScope(Job() + Dispatchers.Main + handler) // Add to scope
                // scope.launch { throw RuntimeException("Error in launch!") }
                ```
            *   **重要特性：**
                *   `CoroutineExceptionHandler` **只是一个“最后一道防线”**，用于记录或报告未处理的异常。它**不能阻止异常的传播**，也不能阻止导致异常的协程及其父 `Job` (如果不是 `SupervisorJob`) 被取消。
                *   它通常安装在根作用域（如 `viewModelScope` 的自定义版本，或 `GlobalScope` - 不推荐）或 `SupervisorJob` 管理的协程的上下文中。
        3.  **`SupervisorJob` / `supervisorScope` (隔离异常)：**
            *   当使用 `SupervisorJob` 创建作用域，或者使用 `supervisorScope { ... }` 构建器时，其直接子协程的失败（抛出异常）**不会取消 `SupervisorJob` 本身，也不会取消其他兄弟子协程。**
            *   失败的子协程的异常仍然会传播，可以被安装在 `SupervisorJob` 作用域或该子协程自身的 `CoroutineExceptionHandler` 捕获。
            ```kotlin
            // val supervisor = SupervisorJob()
            // val scope = CoroutineScope(Dispatchers.Default + supervisor + myExceptionHandler)
            //
            // scope.launch { /* task A */ throw IOException("A failed") } // Failure here is handled by myExceptionHandler, scope and task B are not cancelled
            // scope.launch { /* task B */ delay(1000); println("B done") }
            ```
            *   **`coroutineScope { ... }` vs `supervisorScope { ... }`:**
                *   `coroutineScope`: 如果其内部任何子协程失败，`coroutineScope` 自身会失败并取消所有其他子协程。
                *   `supervisorScope`: 其直接子协程的失败不会导致 `supervisorScope` 失败或取消其他直接子协程。

    *   **异常的透明性：** 协程致力于使异步代码中的异常处理尽可能像同步代码一样直观。`try-catch` 块可以直接包围挂起函数调用。

**3. 示例代码 (How to use?):**

**A. 协作式取消示例:**
```kotlin
// fun main() = runBlocking {
//     val job = launch(Dispatchers.Default) {
//         var i = 0
//         try {
//             while (i < 1000 && isActive) { // Check isActive
//                 if (i % 100 == 0) {
//                     Log.d("CancelDemo", "Working... iteration $i, current thread: ${Thread.currentThread().name}")
//                 }
//                 // yield() // Optionally yield to allow other coroutines and check cancellation
//                 Thread.sleep(10) // Simulate non-suspendable work; delay() would be better
//                                  // If this was a very long non-suspendable blocking call, isActive wouldn't help much during the call
//                 i++
//             }
//         } catch (e: CancellationException) {
//             Log.d("CancelDemo", "Coroutine explicitly cancelled: ${e.message}")
//             throw e // Re-throw if you want the job to be marked as cancelled
//         } finally {
//             Log.d("CancelDemo", "Finally block: Coroutine completed or cancelled at i=$i")
//             // withContext(NonCancellable) { /* suspend fun cleanup */ }
//         }
//     }
//
//     delay(250) // Let it run for a bit
//     Log.d("CancelDemo", "Requesting cancellation...")
//     job.cancelAndJoin() // Cancel the job and wait for its completion
//     Log.d("CancelDemo", "Main: Job is completed.")
// }
```

**B. 异常处理与 SupervisorJob:**
```kotlin
// fun main() = runBlocking {
//     val myExceptionHandler = CoroutineExceptionHandler { _, throwable ->
//         Log.e("ExceptionDemo", "Caught by handler: $throwable")
//     }
//
//     Log.d("ExceptionDemo", "--- Using regular Job (failure propagates) ---")
//     val scopeWithJob = CoroutineScope(Job() + Dispatchers.Default + myExceptionHandler)
//     val jobA = scopeWithJob.launch {
//         Log.d("ExceptionDemo", "JobA: Starting, will succeed.")
//         delay(100)
//         Log.d("ExceptionDemo", "JobA: Finished.")
//     }
//     val jobB = scopeWithJob.launch {
//         Log.d("ExceptionDemo", "JobB: Starting, will fail.")
//         delay(50)
//         throw RuntimeException("JobB failed!")
//     }
//     // Wait for jobA and jobB. Since jobB fails, jobA and scopeWithJob will be cancelled.
//     // The exception handler will be invoked because the scope's job itself fails.
//     joinAll(jobA, jobB) // Or scopeWithJob.coroutineContext[Job]?.join()
//     Log.d("ExceptionDemo", "ScopeWithJob is active: ${scopeWithJob.isActive}") // Likely false
//
//     delay(500) // Separator
//
//     Log.d("ExceptionDemo", "\n--- Using SupervisorJob (failure is isolated) ---")
//     val supervisorScope = CoroutineScope(SupervisorJob() + Dispatchers.Default + myExceptionHandler)
//     val jobC = supervisorScope.launch {
//         Log.d("ExceptionDemo", "JobC (under supervisor): Starting, will succeed.")
//         delay(200)
//         Log.d("ExceptionDemo", "JobC (under supervisor): Finished.")
//     }
//     val jobD = supervisorScope.launch { // This launch itself is a child of SupervisorJob
//         Log.d("ExceptionDemo", "JobD (under supervisor): Starting, will fail.")
//         delay(100)
//         throw IllegalStateException("JobD failed under supervisor!")
//         // This exception is caught by myExceptionHandler.
//         // JobC and supervisorScope itself are NOT cancelled by this failure.
//     }
//     joinAll(jobC, jobD)
//     Log.d("ExceptionDemo", "SupervisorScope is active: ${supervisorScope.isActive}") // Likely true
//     Log.d("ExceptionDemo", "JobC isCancelled: ${jobC.isCancelled}") // false
//     Log.d("ExceptionDemo", "JobD isCompleted: ${jobD.isCompleted}, isCancelled: ${jobD.isCancelled}") // completed=true, cancelled=true (due to its own exception)
//
//     supervisorScope.cancel() // Clean up supervisor scope
// }
```

**4. 实际应用举例 (Real-world project usage?):**

*   **取消：**
    *   用户离开 `Activity`/`Fragment` 时，通过 `viewModelScope.cancel()` 或 `lifecycleScope.cancel()` (自动发生) 取消所有相关的网络请求、数据库查询。
    *   `RecyclerView` 中，当 `ViewHolder` 被回收时，取消其上正在进行的图片加载协程。
    *   用户手动点击“取消下载”按钮，取消正在进行的下载协程。
*   **异常处理：**
    *   在 `ViewModel` 中 `launch` 协程进行网络请求，使用 `try-catch` 捕获 `IOException` 或 `HttpException`，并更新 `LiveData`/`StateFlow` 以向 UI 显示错误信息。
    *   设置全局的 `CoroutineExceptionHandler` (例如在自定义的 Application 级 `CoroutineScope` 中) 来记录那些意外的、未被捕获的协程异常，上报给 Crashlytics 等。
    *   在一个屏幕上并行加载多个独立的数据块（如个人资料、好友列表、最新动态），使用 `supervisorScope` 或 `CoroutineScope(SupervisorJob())`，确保一个数据块加载失败不会影响其他数据块的加载。

**5. 源码解读 (Key implementations, design ideas - 概览):**

*   **`JobSupport.cancelInternal(cause: Throwable)`:** `Job` 取消的核心内部方法。它会将 `Job` 的状态迁移到 Cancelling/Cancelled，并遍历所有子 `Job` 递归调用它们的 `cancelInternal`。
*   **`AbstractCoroutine.resumeWith(result: Result<Any?>)`:** 当协程的 `Continuation` 被恢复时调用。如果 `result` 是一个 `Failure` (包含异常)：
    *   如果是 `CancellationException`，则正常完成取消流程。
    *   如果是其他异常，则会尝试通知父 `Job` 该异常 (`parent.childCancelled(exception)` 或类似机制)，这通常会导致父 `Job` 被取消（除非是 `SupervisorJob`）。
*   **`SupervisorJob` 的实现：** 它重写了处理子协程失败的方法 (如 `childCancelled(cause: Throwable): Boolean`)，使其返回 `false`，表示它自己不因子的失败而被取消，从而阻止了异常向上传播导致父级或兄弟的取消。

**6. 优缺点 / 适用场景 / 局限性 (Pros & Cons / When to use / Limitations):**

*   **优点：**
    *   **结构化的取消：** 自动、可预测的取消传播。
    *   **结构化的异常处理：** 异常按父子关系传播，易于统一处理。
    *   **减少资源泄漏和僵尸任务。**
    *   **代码更健壮、更易于推理。**
*   **缺点/局限性：**
    *   **协作式取消：** 需要协程代码配合才能有效取消。长时间运行的非挂起阻塞代码无法直接通过协程取消机制中断（需要 `Thread.interrupt()`，或将阻塞代码移到可中断的协程中）。
    *   **`CoroutineExceptionHandler` 的作用范围需要理解清楚。**

*   **适用场景：** 所有使用 Kotlin 协程的场景都应充分利用其取消和异常处理机制。

**7. 最佳实践 / 注意事项 / common pitfalls:**

*   **始终在合适的 `CoroutineScope` 中启动协程**，以便利用结构化并发进行生命周期管理。
*   **确保长时间运行的循环或计算是可取消的** (检查 `isActive` 或使用可取消的挂起函数)。
*   **使用 `try-catch` 处理协程中可预期的异常。**
*   **为顶级协程或使用 `SupervisorJob` 的作用域配置 `CoroutineExceptionHandler`** 来记录/报告未处理的异常。
*   **在 `finally` 块中执行必要的资源清理**，如果清理操作是挂起的，使用 `withContext(NonCancellable)`。
*   **理解 `async` 的异常处理方式：** 异常在 `await()` 时抛出。如果多个 `async` 并行，可以使用 `supervisorScope` 包装它们，并分别 `try-catch` 每个 `await()` 调用，或者让 `supervisorScope` 的 `CoroutineExceptionHandler` 处理。
*   **不要在协程中“吞掉” `CancellationException`** (即 `catch (e: CancellationException) { /* do nothing or just log */ }` 然后不重新抛出)，这会破坏协程的取消机制。如果确实需要捕获它做清理，清理后应重新抛出 `throw e`，或者确保协程的后续代码不再执行。

**8. 对比 (协程异常处理 vs 传统线程异常处理):**

| 特性         | 协程异常处理                                 | 传统线程 (`Thread`, `ExecutorService`)       |
| :----------- | :------------------------------------------- | :------------------------------------------- |
| **传播**     | 结构化，向父 Job 传播 (默认)                 | 线程内未捕获异常通常导致线程终止，需 `UncaughtExceptionHandler` |
| **统一处理** | `CoroutineExceptionHandler` (顶级/Supervisor) | 每个线程或 `ExecutorService` 需单独配置     |
| **取消关联** | 异常可导致相关协程自动取消                   | 通常无自动关联取消                           |
| **`async`**  | 异常延迟到 `await()`                          | `Future.get()` 抛出 `ExecutionException`     |

**9. 相关面试题及思考:**

*   **问题1：** Kotlin 协程的取消机制是如何工作的？为什么说是“协作式”的？
    *   **思考：** 抛 `CancellationException`，协程代码需检查 `isActive` 或调用可取消的挂起函数。
*   **问题2：** 如何在协程被取消后执行清理操作？如果在清理操作中需要调用挂起函数怎么办？
    *   **思考：** `try-finally`。挂起清理用 `withContext(NonCancellable)`。
*   **问题3：** `Job` 和 `SupervisorJob` 在异常处理方面有什么核心区别？
    *   **思考：** `Job`: 子失败 -> 父失败 -> 兄弟取消。`SupervisorJob`: 子失败不影响父或兄弟。
*   **问题4：** `CoroutineExceptionHandler` 的作用是什么？它能阻止异常的传播吗？
    *   **思考：** 处理未捕获的顶级/Supervisor子协程异常。不能阻止传播（除非异常是 `CancellationException`），主要用于日志/报告。
*   **问题5：** `async` 构建的协程如果内部发生异常，这个异常何时何地会被抛出？
    *   **思考：** 存储在 `Deferred` 中，调用 `await()` 时抛出。
*   **问题6：** 如果你在一个 `viewModelScope.launch` 中启动了两个子 `launch` 块，其中一个子 `launch` 失败了（非 `CancellationException`），另一个子 `launch` 会怎么样？`viewModelScope` 本身呢？
    *   **思考：** `viewModelScope` 默认使用 `SupervisorJob` + `CoroutineExceptionHandler`。因此，一个子 `launch` 失败，异常会被 Handler 处理，另一个子 `launch` 和 `viewModelScope` 本身不会被取消。
*   **问题7：** `withTimeout` 和 `withTimeoutOrNull` 有什么区别？
    *   **思考：** 超时时前者抛 `TimeoutCancellationException`，后者返回 `null`。
*   **问题8：** 为什么不应该在协程中捕获 `CancellationException` 后不进行任何处理或不重新抛出？
    *   **思考：** 会破坏结构化并发的取消传播机制。

---
