
**Android 复习笔记 - 1.4.4 Flow 的异常处理 (catch, onCompletion, retry)**

**1. 核心价值 / 解决的问题 (Why it exists / What problem it solves):**

*   **核心价值：** 在处理异步数据流时，异常和完成状态的处理是保证代码健壮性和良好用户体验的关键。Kotlin Flow 提供了一套声明式且与协程集成的操作符来优雅地捕获异常、在流完成时执行清理逻辑，以及实现重试机制。
*   **解决的问题：**
    *   **未捕获异常导致应用崩溃：** 如果 Flow 的生产者或中间操作符中发生异常而未被处理，异常会传播到收集者 (`collect`)，如果收集者也没有处理，则可能导致协程失败甚至应用崩溃。
    *   **分散的错误处理逻辑：** 在每个 `collect` 块中都写 `try-catch` 会很冗余。
    *   **资源清理不及时：** 当 Flow 正常完成、发生错误或被取消时，可能需要执行一些资源释放操作。
    *   **网络抖动或临时性错误：** 对于可恢复的错误，希望能够自动或有条件地重试失败的操作。

**2. 知识点阐述 (Is what? Core principles?):**

*   **2.1 Flow 中的异常透明性 (Exception Transparency):**
    *   **原则：** Flow 的构建器 (`flow { ... }`) 和大多数中间操作符内部不应该直接使用 `try-catch` 来“吞掉”异常。它们应该让异常“透明地”流向下游，由末端操作符 (`collect`) 或专门的错误处理操作符 (`catch`) 来处理。
    *   **`emit()` 的行为：** 如果 `FlowCollector.emit()` 在下游的 `collect` 块中抛出异常，这个异常也会传播给上游的生产者。
    *   **`CancellationException`：** 是一个例外，它用于协程的正常取消流程，通常会被 Flow 框架自身处理，不会被普通的 `catch` 操作符捕获（除非 `catch` 块明确捕获 `Throwable` 并检查类型）。

*   **2.2 `catch { cause: Throwable -> ... }` 操作符 (声明式异常捕获):**
    *   **作用：** 用于捕获其**上游 Flow** (即 `catch` 之前的所有生产者和中间操作符) 中发生的异常。
    *   **行为：**
        *   当上游 Flow 抛出异常时，该异常会被 `catch` 操作符的 Lambda 捕获。
        *   在 `catch` 的 Lambda 内部，你可以：
            *   记录日志。
            *   发出一个或多个备用值 (fallback value) 以替代错误状态：`emit(defaultValue)`。
            *   发出一个表示错误的特定对象：`emit(ErrorState(cause))`。
            *   重新抛出原始异常 (`throw cause`) 或抛出一个新的异常，让下游（或外部的 `try-catch`）处理。
            *   什么都不做（即忽略异常，Flow 会在此处正常完成，不再发出任何值）。
        *   `catch` 操作符**只能捕获上游的异常**，它无法捕获下游（即 `catch` 之后的操作符或 `collect` 块中）发生的异常。
    *   **位置：** `catch` 操作符的位置很重要，它只影响其之前的操作。可以有多个 `catch` 来处理不同阶段的异常。
    ```kotlin
    // flow {
    //     Log.d(TAG, "Emitting 1")
    //     emit(1)
    //     Log.d(TAG, "Emitting 2 (will throw)")
    //     throw RuntimeException("Error in producer!")
    //     // emit(2) // This won't be reached
    // }
    // .map { value ->
    //     Log.d(TAG, "Mapping $value")
    //     if (value == 1) "Value: $value" else throw IllegalStateException("Error in map!")
    // }
    // .catch { e -> // Catches exceptions from flow builder AND map operator
    //     Log.e(TAG, "Caught exception: $e")
    //     emit("Fallback on error") // Emit a fallback value
    // }
    // .collect { value ->
    //     Log.d(TAG, "Collected: $value")
    // }
    // // Output might be:
    // // Emitting 1
    // // Mapping 1
    // // Collected: Value: 1
    // // Emitting 2 (will throw)
    // // Caught exception: java.lang.RuntimeException: Error in producer!
    // // Collected: Fallback on error
    ```

*   **2.3 `onCompletion { cause: Throwable? -> ... }` 操作符 (完成时回调):**
    *   **作用：** 在 Flow **完成**时（无论是正常完成、因异常终止还是被取消）执行给定的 Lambda 块。
    *   **行为：**
        *   `cause` 参数：
            *   如果 Flow 正常完成，`cause` 为 `null`。
            *   如果 Flow 因上游异常而终止，`cause` 为该异常。
            *   如果 Flow 被取消，`cause` 为 `CancellationException`。
        *   `onCompletion` 的 Lambda **不能发出新的值** (`emit`) 到下游。它主要用于执行副作用，如资源清理、隐藏加载指示器等。
        *   **执行顺序：** `onCompletion` 在 `catch` 之后、`collect` (如果 Flow 未因异常提前终止) 完成之前或异常传播到 `collect` 之前执行。更准确地说，它在收集者处理完所有元素或收到异常信号之后，但在收集协程真正结束之前。
        *   **与 `finally` 块的区别：**
            *   `try { flow.collect() } finally { ... }` 中的 `finally` 块在 `collect` 协程结束时执行。
            *   `onCompletion` 是 Flow 自身完成（或终止）时执行，不依赖于 `collect` 是否被 `try-catch` 包裹。
            *   `onCompletion` 知道 Flow 完成的原因 (`cause`)。
    ```kotlin
    // flow {
    //     emit(1); delay(100)
    //     emit(2); delay(100)
    //     // throw IOException("Simulated error") // Uncomment to test error case
    // }
    // .onCompletion { cause ->
    //     if (cause != null) Log.d(TAG, "Flow completed with error: $cause")
    //     else Log.d(TAG, "Flow completed successfully")
    //     // Hide loading indicator here
    // }
    // .catch { e -> Log.e(TAG, "Caught in catch: $e") } // Catch is upstream of onCompletion's data flow, but onCompletion still sees the cause
    // .collect { value -> Log.d(TAG, "Collected: $value") }
    ```

*   **2.4 重试操作符 (`retry` 和 `retryWhen`):**
    *   用于在 Flow 发生异常时自动重新订阅 (即重新执行) 上游 Flow。
    *   **`retry(retries: Long = Long.MAX_VALUE, predicate: suspend (cause: Throwable) -> Boolean = { true }): Flow<T>`:**
        *   当上游 Flow 抛出异常时，如果 `predicate` 对该异常返回 `true`，则会重新订阅上游 Flow。
        *   `retries`: 最大重试次数。
        *   **注意：** 如果不加限制，简单的 `retry()` 可能会在持续失败的情况下导致无限重试。
        *   通常与 `delay` (在 `predicate` 或 `retryWhen` 中) 结合使用，实现退避重试。
    *   **`retryWhen(predicate: suspend FlowCollector<T>.(cause: Throwable, attempt: Long) -> Boolean): Flow<T>`:**
        *   更灵活的重试机制。`predicate` Lambda 的接收者是 `FlowCollector<T>`，允许在重试前发出值。
        *   `attempt`: 当前是第几次重试 (从 0 开始)。
        *   `predicate` 返回 `true` 表示重试，返回 `false` 表示不再重试并将异常向下游传播。
        *   可以在 `predicate` 内部实现自定义的退避逻辑 (如指数退避 `delay(attempt * 1000L)` )。
    ```kotlin
    // var attemptCount = 0
    // fun fetchDataFlow(): Flow<String> = flow {
    //     attemptCount++
    //     Log.d(TAG, "Attempting to fetch data, attempt: $attemptCount")
    //     delay(500)
    //     if (attemptCount < 3) {
    //         throw IOException("Network error on attempt $attemptCount")
    //     }
    //     emit("Data fetched successfully on attempt $attemptCount")
    // }
    //
    // fetchDataFlow()
    //     .retryWhen { cause, attempt ->
    //         if (cause is IOException && attempt < 3) { // Retry max 3 times for IOExceptions
    //             val delayMillis = 1000L * (attempt + 1) // Exponential backoff (simple version)
    //             Log.d(TAG, "Retrying in ${delayMillis}ms after attempt $attempt due to $cause")
    //             delay(delayMillis)
    //             true // Retry
    //         } else {
    //             false // Don't retry for other exceptions or too many attempts
    //         }
    //     }
    //     .catch { e -> Log.e(TAG, "Final error after retries: $e") }
    //     .collect { data -> Log.d(TAG, "Collected successfully: $data") }
    ```

*   **2.5 命令式异常处理 (Imperative Exception Handling):**
    *   除了声明式的 `catch` 操作符，仍然可以在收集 Flow 的协程中使用传统的 `try-catch` 块。
    *   **`try-catch` 包裹 `collect()`:** 可以捕获来自上游 Flow（如果 `catch` 操作符未处理或重新抛出）以及 `collect` Lambda 自身内部抛出的异常。
    ```kotlin
    // try {
    //     myFlow.collect { value ->
    //         if (value == "bad") throw IllegalStateException("Bad value in collect")
    //         println(value)
    //     }
    // } catch (e: Throwable) { // Catches exceptions from myFlow producer or collect block
    //     println("Caught in collect's try-catch: $e")
    // }
    ```

**3. 示例代码 (How to use?):**

**(已在 2.2, 2.3, 2.4 中给出了各个操作符的示例。)**

**一个更完整的错误处理和完成流程示例:**
```kotlin
import kotlinx.coroutines.*
import kotlinx.coroutines.flow.*

fun dataSourceFlow(id: Int): Flow<String> = flow {
    Log.d("DataSource", "Starting data source for id: $id")
    emit("Initial data for $id")
    delay(200)
    if (id == 2) {
        throw IllegalStateException("ID 2 is problematic!")
    }
    emit("Updated data for $id")
    delay(100)
    Log.d("DataSource", "Data source for id: $id finished normally")
}

fun main() = runBlocking {
    val idsToProcess = listOf(1, 2, 3).asFlow()

    idsToProcess
        .onEach { id -> Log.d("MainFlow", "Processing ID: $id") }
        .flatMapMerge { id -> // Process each ID's flow concurrently
            dataSourceFlow(id)
                .map { data -> "Transformed: $data" }
                .catch { e -> // Catch errors specific to this inner dataSourceFlow
                    Log.e("InnerCatch", "Error for ID $id: ${e.message}")
                    emit("Error placeholder for ID $id") // Emit a fallback for this ID
                }
        }
        .onStart { Log.d("MainFlow", "Main flow collection started.") }
        .onCompletion { cause ->
            // This 'cause' will be from the flatMapMerge or idsToProcess if they fail,
            // or null if all inner flows (after their catches) complete.
            if (cause != null) {
                Log.e("MainFlow", "Main flow completed with an unhandled error: $cause")
            } else {
                Log.i("MainFlow", "Main flow collection completed.")
            }
        }
        .catch { e -> // Catch any errors not handled by inner catches or from flatMapMerge itself
            Log.e("OuterCatch", "Critical error in main flow processing: $e")
            // This might not be reached if all inner flows handle their errors and emit fallbacks.
        }
        .collect { result ->
            Log.d("MainFlow", "Collected final result: $result")
        }
}
```

**4. 实际应用举例 (Real-world project usage?):**

*   **`catch`:**
    *   从网络 API 获取数据的 Flow，如果发生 `IOException`，则 `emit` 一个从本地缓存读取的旧数据或一个空列表/错误状态对象。
    *   记录 Flow 中发生的特定异常到日志系统。
*   **`onCompletion`:**
    *   在数据加载 Flow (如从网络或数据库) 完成后（无论成功或失败），隐藏一个加载中的 `ProgressBar`。
    *   释放 Flow 处理过程中占用的资源（如关闭文件流，尽管 `use` 扩展函数更适合此场景）。
*   **`retry` / `retryWhen`:**
    *   对于可能会因网络抖动而临时失败的网络请求 Flow，使用 `retryWhen` 实现带有延迟的指数退避重试策略，尝试几次后若仍失败则放弃。
    *   轮询某个 API 直到获取到特定状态或数据，每次轮询失败后延迟一段时间再重试。

**5. 源码解读 (Key implementations, design ideas - 概览):**

*   **`catch` 操作符的实现 (`CatchFlow`):**
    *   它会创建一个新的 `Flow` 实例。
    *   在其 `collectSafely` 方法中，它会 `try-catch` 包裹对上游 `Flow` 的 `collect` 调用。
    *   如果捕获到异常，它会调用用户提供的 `catch` Lambda，并将 `FlowCollector` (下游的) 和异常实例传递给它。用户可以在此 Lambda 中 `emit` 新值或重新抛出异常。
*   **`onCompletion` 操作符的实现 (`SafeFlow` / `ChannelFlow` 的变体):**
    *   它也会包装上游 Flow。在其 `collectSafely` 中，使用 `try-finally` 结构。
    *   在 `finally` 块中（或类似机制确保在完成、错误或取消时都执行），调用用户提供的 `onCompletion` Lambda，并传递 `cause`。
*   **`retryWhen` 操作符的实现：**
    *   内部通常有一个循环，在循环中 `try-catch` 包裹对上游 Flow 的 `collect`。
    *   如果发生异常，调用用户提供的 `predicate` Lambda (包含 `cause` 和 `attempt`计数)。
    *   如果 `predicate` 返回 `true` (并可能执行了 `delay`)，则继续下一次循环（即重试）。
    *   如果 `predicate` 返回 `false`，则将异常抛出，终止重试。

**6. 优缺点 / 适用场景 / 局限性 (Pros & Cons / When to use / Limitations):**

*   **优点：**
    *   **声明式错误处理：** 使错误处理逻辑更清晰，与数据流管道集成。
    *   **统一的完成回调：** `onCompletion` 方便进行资源清理和最终状态处理。
    *   **强大的重试机制：** `retryWhen` 提供了灵活的自定义重试逻辑。
    *   **与协程的取消和异常传播机制良好配合。**
*   **缺点/局限性：**
    *   `catch` 操作符只捕获上游异常，需要注意其放置位置。
    *   `onCompletion` 不能发出新值影响下游。
    *   过度使用复杂的 `retryWhen` 逻辑可能使代码难以理解。

*   **适用场景：**
    *   任何需要处理异步数据流中可能发生的错误、需要在流结束时执行清理或需要实现重试逻辑的场景。

**7. 最佳实践 / 注意事项 / common pitfalls:**

*   **将 `catch` 操作符放在尽可能靠近可能发生异常的源头，或者放在你希望开始处理该异常并可能提供备用数据的地方。**
*   **在 `catch` 块中，要么 `emit` 一个替代值/状态，要么重新 `throw` 异常 (或其包装)，不要“吞掉”所有异常而不做任何处理或记录，这会使调试困难。**
*   **使用 `onCompletion` 进行资源清理或最终的 UI 状态更新（如隐藏加载）。**
*   **谨慎设计 `retryWhen` 的逻辑，避免无限重试。** 设置最大重试次数，并使用合理的退避策略（如指数退避加随机抖动）。
*   **`CancellationException` 通常不应被 `catch` 操作符捕获并处理为普通错误，** 因为它是协程正常取消的一部分。如果确实需要捕获它做特殊清理，清理后应重新抛出。
*   **区分 Flow 完成（无错误）和 Flow 因错误终止：** `onCompletion` 的 `cause` 参数可以帮助区分。
*   **测试错误处理和重试逻辑**，确保它们在各种失败场景下按预期工作。

**8. 对比 (Flow 异常处理 vs 传统 try-catch vs RxJava 错误处理):**

*   **Flow `catch` vs 传统 `try-catch` 包裹 `collect`:**
    *   `catch` 操作符更声明式，可以链式调用，只处理上游异常。
    *   `try-catch` 包裹 `collect` 可以捕获上游未处理的异常以及 `collect` 块自身的异常。两者可以结合使用。
*   **Flow 异常处理 vs RxJava `onError` / `doOnError` / `retry`:**
    *   概念上类似，都提供了声明式的错误处理和重试机制。
    *   Flow 的实现基于协程和挂起函数，与 Kotlin 语言集成更紧密。
    *   RxJava 的操作符生态系统可能更庞大一些，但 Flow 也在不断完善。

**9. 相关面试题及思考:**

*   **问题1：** Kotlin Flow 中的 `catch` 操作符是如何工作的？它能捕获哪些异常？
    *   **思考：** 捕获上游异常。不能捕获下游或 `collect` 块中的异常。
*   **问题2：** `onCompletion` 操作符在 Flow 的什么阶段执行？它的 `cause` 参数有什么含义？
    *   **思考：** Flow 完成时（正常、错误、取消）。`cause` 表示完成原因。
*   **问题3：** 如果你想在一个 Flow 失败时自动重试几次，并带有一定的延迟，你会使用哪个操作符？如何实现？
    *   **思考：** `retryWhen`。在 predicate 中检查 `cause` 和 `attempt`，使用 `delay()`。
*   **问题4：** “异常透明性”在 Flow 中是什么意思？
    *   **思考：** 生产者和中间操作符不应私自 `try-catch` 吞掉异常，应让其流向下游由 `catch` 或 `collect` 处理。
*   **问题5：** `CancellationException` 在 Flow 的异常处理中有什么特殊性？
    *   **思考：** 通常不被 `catch` 捕获，代表正常取消，`onCompletion` 的 `cause` 会是它。
*   **问题6：** 如果一个 Flow 有多个 `catch` 操作符，它们的执行顺序和作用范围是怎样的？
    *   **思考：** 每个 `catch` 只处理其直接上游的异常。一旦一个 `catch` 处理了异常并 `emit` 了新值（或没有重新抛出），下游的 `catch` 就不会再收到那个原始异常。
*   **问题7：** 在 `onCompletion` 中可以 `emit` 新的值吗？
    *   **思考：** 不可以。它用于副作用和清理。
*   **问题8：** 你会如何在 `ViewModel` 中使用 Flow 并处理其可能发生的网络或数据库错误，然后将结果（成功数据或错误状态）安全地更新到 UI？
    *   **思考：** `ViewModel` 中 `launch` 协程收集 Flow，使用 `flowOn` 切换IO，使用 `catch` 转换错误为 UI 状态，通过 `StateFlow` 或 `LiveData` 暴露给 UI。UI 层观察并显示。

---
